{
 "cells": [
  {
   "cell_type": "markdown",
   "metadata": {},
   "source": [
    "# Headers"
   ]
  },
  {
   "cell_type": "code",
   "execution_count": 1,
   "metadata": {},
   "outputs": [
    {
     "name": "stderr",
     "output_type": "stream",
     "text": [
      "\n",
      "A module that was compiled using NumPy 1.x cannot be run in\n",
      "NumPy 2.0.2 as it may crash. To support both 1.x and 2.x\n",
      "versions of NumPy, modules must be compiled with NumPy 2.0.\n",
      "Some module may need to rebuild instead e.g. with 'pybind11>=2.12'.\n",
      "\n",
      "If you are a user of the module, the easiest solution will be to\n",
      "downgrade to 'numpy<2' or try to upgrade the affected module.\n",
      "We expect that some modules will need time to support NumPy 2.\n",
      "\n",
      "Traceback (most recent call last):  File \"<frozen runpy>\", line 198, in _run_module_as_main\n",
      "  File \"<frozen runpy>\", line 88, in _run_code\n",
      "  File \"C:\\Users\\PLour\\AppData\\Local\\Packages\\PythonSoftwareFoundation.Python.3.11_qbz5n2kfra8p0\\LocalCache\\local-packages\\Python311\\site-packages\\ipykernel_launcher.py\", line 18, in <module>\n",
      "    app.launch_new_instance()\n",
      "  File \"C:\\Users\\PLour\\AppData\\Local\\Packages\\PythonSoftwareFoundation.Python.3.11_qbz5n2kfra8p0\\LocalCache\\local-packages\\Python311\\site-packages\\traitlets\\config\\application.py\", line 1075, in launch_instance\n",
      "    app.start()\n",
      "  File \"C:\\Users\\PLour\\AppData\\Local\\Packages\\PythonSoftwareFoundation.Python.3.11_qbz5n2kfra8p0\\LocalCache\\local-packages\\Python311\\site-packages\\ipykernel\\kernelapp.py\", line 739, in start\n",
      "    self.io_loop.start()\n",
      "  File \"C:\\Users\\PLour\\AppData\\Local\\Packages\\PythonSoftwareFoundation.Python.3.11_qbz5n2kfra8p0\\LocalCache\\local-packages\\Python311\\site-packages\\tornado\\platform\\asyncio.py\", line 205, in start\n",
      "    self.asyncio_loop.run_forever()\n",
      "  File \"C:\\Program Files\\WindowsApps\\PythonSoftwareFoundation.Python.3.11_3.11.2544.0_x64__qbz5n2kfra8p0\\Lib\\asyncio\\base_events.py\", line 608, in run_forever\n",
      "    self._run_once()\n",
      "  File \"C:\\Program Files\\WindowsApps\\PythonSoftwareFoundation.Python.3.11_3.11.2544.0_x64__qbz5n2kfra8p0\\Lib\\asyncio\\base_events.py\", line 1936, in _run_once\n",
      "    handle._run()\n",
      "  File \"C:\\Program Files\\WindowsApps\\PythonSoftwareFoundation.Python.3.11_3.11.2544.0_x64__qbz5n2kfra8p0\\Lib\\asyncio\\events.py\", line 84, in _run\n",
      "    self._context.run(self._callback, *self._args)\n",
      "  File \"C:\\Users\\PLour\\AppData\\Local\\Packages\\PythonSoftwareFoundation.Python.3.11_qbz5n2kfra8p0\\LocalCache\\local-packages\\Python311\\site-packages\\ipykernel\\kernelbase.py\", line 545, in dispatch_queue\n",
      "    await self.process_one()\n",
      "  File \"C:\\Users\\PLour\\AppData\\Local\\Packages\\PythonSoftwareFoundation.Python.3.11_qbz5n2kfra8p0\\LocalCache\\local-packages\\Python311\\site-packages\\ipykernel\\kernelbase.py\", line 534, in process_one\n",
      "    await dispatch(*args)\n",
      "  File \"C:\\Users\\PLour\\AppData\\Local\\Packages\\PythonSoftwareFoundation.Python.3.11_qbz5n2kfra8p0\\LocalCache\\local-packages\\Python311\\site-packages\\ipykernel\\kernelbase.py\", line 437, in dispatch_shell\n",
      "    await result\n",
      "  File \"C:\\Users\\PLour\\AppData\\Local\\Packages\\PythonSoftwareFoundation.Python.3.11_qbz5n2kfra8p0\\LocalCache\\local-packages\\Python311\\site-packages\\ipykernel\\ipkernel.py\", line 362, in execute_request\n",
      "    await super().execute_request(stream, ident, parent)\n",
      "  File \"C:\\Users\\PLour\\AppData\\Local\\Packages\\PythonSoftwareFoundation.Python.3.11_qbz5n2kfra8p0\\LocalCache\\local-packages\\Python311\\site-packages\\ipykernel\\kernelbase.py\", line 778, in execute_request\n",
      "    reply_content = await reply_content\n",
      "  File \"C:\\Users\\PLour\\AppData\\Local\\Packages\\PythonSoftwareFoundation.Python.3.11_qbz5n2kfra8p0\\LocalCache\\local-packages\\Python311\\site-packages\\ipykernel\\ipkernel.py\", line 449, in do_execute\n",
      "    res = shell.run_cell(\n",
      "  File \"C:\\Users\\PLour\\AppData\\Local\\Packages\\PythonSoftwareFoundation.Python.3.11_qbz5n2kfra8p0\\LocalCache\\local-packages\\Python311\\site-packages\\ipykernel\\zmqshell.py\", line 549, in run_cell\n",
      "    return super().run_cell(*args, **kwargs)\n",
      "  File \"C:\\Users\\PLour\\AppData\\Local\\Packages\\PythonSoftwareFoundation.Python.3.11_qbz5n2kfra8p0\\LocalCache\\local-packages\\Python311\\site-packages\\IPython\\core\\interactiveshell.py\", line 3075, in run_cell\n",
      "    result = self._run_cell(\n",
      "  File \"C:\\Users\\PLour\\AppData\\Local\\Packages\\PythonSoftwareFoundation.Python.3.11_qbz5n2kfra8p0\\LocalCache\\local-packages\\Python311\\site-packages\\IPython\\core\\interactiveshell.py\", line 3130, in _run_cell\n",
      "    result = runner(coro)\n",
      "  File \"C:\\Users\\PLour\\AppData\\Local\\Packages\\PythonSoftwareFoundation.Python.3.11_qbz5n2kfra8p0\\LocalCache\\local-packages\\Python311\\site-packages\\IPython\\core\\async_helpers.py\", line 128, in _pseudo_sync_runner\n",
      "    coro.send(None)\n",
      "  File \"C:\\Users\\PLour\\AppData\\Local\\Packages\\PythonSoftwareFoundation.Python.3.11_qbz5n2kfra8p0\\LocalCache\\local-packages\\Python311\\site-packages\\IPython\\core\\interactiveshell.py\", line 3334, in run_cell_async\n",
      "    has_raised = await self.run_ast_nodes(code_ast.body, cell_name,\n",
      "  File \"C:\\Users\\PLour\\AppData\\Local\\Packages\\PythonSoftwareFoundation.Python.3.11_qbz5n2kfra8p0\\LocalCache\\local-packages\\Python311\\site-packages\\IPython\\core\\interactiveshell.py\", line 3517, in run_ast_nodes\n",
      "    if await self.run_code(code, result, async_=asy):\n",
      "  File \"C:\\Users\\PLour\\AppData\\Local\\Packages\\PythonSoftwareFoundation.Python.3.11_qbz5n2kfra8p0\\LocalCache\\local-packages\\Python311\\site-packages\\IPython\\core\\interactiveshell.py\", line 3577, in run_code\n",
      "    exec(code_obj, self.user_global_ns, self.user_ns)\n",
      "  File \"C:\\Users\\PLour\\AppData\\Local\\Temp\\ipykernel_9172\\3802135991.py\", line 6, in <module>\n",
      "    from tsai.all import *\n",
      "  File \"C:\\Users\\PLour\\AppData\\Local\\Packages\\PythonSoftwareFoundation.Python.3.11_qbz5n2kfra8p0\\LocalCache\\local-packages\\Python311\\site-packages\\tsai\\all.py\", line 2, in <module>\n",
      "    from .imports import *\n",
      "  File \"C:\\Users\\PLour\\AppData\\Local\\Packages\\PythonSoftwareFoundation.Python.3.11_qbz5n2kfra8p0\\LocalCache\\local-packages\\Python311\\site-packages\\tsai\\imports.py\", line 50, in <module>\n",
      "    import torch\n",
      "  File \"C:\\Users\\PLour\\AppData\\Local\\Packages\\PythonSoftwareFoundation.Python.3.11_qbz5n2kfra8p0\\LocalCache\\local-packages\\Python311\\site-packages\\torch\\__init__.py\", line 1477, in <module>\n",
      "    from .functional import *  # noqa: F403\n",
      "  File \"C:\\Users\\PLour\\AppData\\Local\\Packages\\PythonSoftwareFoundation.Python.3.11_qbz5n2kfra8p0\\LocalCache\\local-packages\\Python311\\site-packages\\torch\\functional.py\", line 9, in <module>\n",
      "    import torch.nn.functional as F\n",
      "  File \"C:\\Users\\PLour\\AppData\\Local\\Packages\\PythonSoftwareFoundation.Python.3.11_qbz5n2kfra8p0\\LocalCache\\local-packages\\Python311\\site-packages\\torch\\nn\\__init__.py\", line 1, in <module>\n",
      "    from .modules import *  # noqa: F403\n",
      "  File \"C:\\Users\\PLour\\AppData\\Local\\Packages\\PythonSoftwareFoundation.Python.3.11_qbz5n2kfra8p0\\LocalCache\\local-packages\\Python311\\site-packages\\torch\\nn\\modules\\__init__.py\", line 35, in <module>\n",
      "    from .transformer import TransformerEncoder, TransformerDecoder, \\\n",
      "  File \"C:\\Users\\PLour\\AppData\\Local\\Packages\\PythonSoftwareFoundation.Python.3.11_qbz5n2kfra8p0\\LocalCache\\local-packages\\Python311\\site-packages\\torch\\nn\\modules\\transformer.py\", line 20, in <module>\n",
      "    device: torch.device = torch.device(torch._C._get_default_device()),  # torch.device('cpu'),\n",
      "C:\\Users\\PLour\\AppData\\Local\\Packages\\PythonSoftwareFoundation.Python.3.11_qbz5n2kfra8p0\\LocalCache\\local-packages\\Python311\\site-packages\\torch\\nn\\modules\\transformer.py:20: UserWarning: Failed to initialize NumPy: _ARRAY_API not found (Triggered internally at ..\\torch\\csrc\\utils\\tensor_numpy.cpp:84.)\n",
      "  device: torch.device = torch.device(torch._C._get_default_device()),  # torch.device('cpu'),\n"
     ]
    },
    {
     "ename": "ImportError",
     "evalue": "cannot import name 'TimeSeriesDataLoaders' from 'tsai.data' (C:\\Users\\PLour\\AppData\\Local\\Packages\\PythonSoftwareFoundation.Python.3.11_qbz5n2kfra8p0\\LocalCache\\local-packages\\Python311\\site-packages\\tsai\\data\\__init__.py)",
     "output_type": "error",
     "traceback": [
      "\u001b[1;31m---------------------------------------------------------------------------\u001b[0m",
      "\u001b[1;31mImportError\u001b[0m                               Traceback (most recent call last)",
      "Cell \u001b[1;32mIn[1], line 7\u001b[0m\n\u001b[0;32m      5\u001b[0m \u001b[38;5;66;03m# Models\u001b[39;00m\n\u001b[0;32m      6\u001b[0m \u001b[38;5;28;01mfrom\u001b[39;00m \u001b[38;5;21;01mtsai\u001b[39;00m\u001b[38;5;21;01m.\u001b[39;00m\u001b[38;5;21;01mall\u001b[39;00m \u001b[38;5;28;01mimport\u001b[39;00m \u001b[38;5;241m*\u001b[39m\n\u001b[1;32m----> 7\u001b[0m \u001b[38;5;28;01mfrom\u001b[39;00m \u001b[38;5;21;01mtsai\u001b[39;00m\u001b[38;5;21;01m.\u001b[39;00m\u001b[38;5;21;01mdata\u001b[39;00m \u001b[38;5;28;01mimport\u001b[39;00m TimeSeriesDataLoaders\n\u001b[0;32m     10\u001b[0m \u001b[38;5;66;03m# Metrics\u001b[39;00m\n\u001b[0;32m     11\u001b[0m \u001b[38;5;28;01mfrom\u001b[39;00m \u001b[38;5;21;01msklearn\u001b[39;00m\u001b[38;5;21;01m.\u001b[39;00m\u001b[38;5;21;01mmetrics\u001b[39;00m \u001b[38;5;28;01mimport\u001b[39;00m accuracy_score, f1_score\n",
      "\u001b[1;31mImportError\u001b[0m: cannot import name 'TimeSeriesDataLoaders' from 'tsai.data' (C:\\Users\\PLour\\AppData\\Local\\Packages\\PythonSoftwareFoundation.Python.3.11_qbz5n2kfra8p0\\LocalCache\\local-packages\\Python311\\site-packages\\tsai\\data\\__init__.py)"
     ]
    }
   ],
   "source": [
    "import pandas as pd\n",
    "import time\n",
    "import numpy as np\n",
    "\n",
    "# Models\n",
    "from tsai.all import *\n",
    "from tsai.data import TimeSeriesDataLoaders\n",
    "\n",
    "\n",
    "# Metrics\n",
    "from sklearn.metrics import accuracy_score, f1_score"
   ]
  },
  {
   "cell_type": "code",
   "execution_count": null,
   "metadata": {},
   "outputs": [],
   "source": [
    "from data_treatment import train_df, test_df, \\\n",
    "                            treated_train_df, treated_test_df, \\\n",
    "                            new_features_train_df, new_features_test_df, \\\n",
    "                            svd_train_df, svd_test_df, \\\n",
    "                            targets_for_test_df\n",
    "\n",
    "from data_treatment import train_val_split"
   ]
  },
  {
   "cell_type": "markdown",
   "metadata": {},
   "source": [
    "# Data Processing"
   ]
  },
  {
   "cell_type": "code",
   "execution_count": null,
   "metadata": {},
   "outputs": [
    {
     "ename": "NameError",
     "evalue": "name 'TimeSeriesDataSet' is not defined",
     "output_type": "error",
     "traceback": [
      "\u001b[1;31m---------------------------------------------------------------------------\u001b[0m",
      "\u001b[1;31mNameError\u001b[0m                                 Traceback (most recent call last)",
      "Cell \u001b[1;32mIn[5], line 8\u001b[0m\n\u001b[0;32m      5\u001b[0m X_train, y_train, X_val, y_val \u001b[38;5;241m=\u001b[39m train_val_split(treated_train_df)\n\u001b[0;32m      7\u001b[0m \u001b[38;5;66;03m# Convert the training and validation data into a TimeSeriesDataSet\u001b[39;00m\n\u001b[1;32m----> 8\u001b[0m train_ds \u001b[38;5;241m=\u001b[39m \u001b[43mTimeSeriesDataSet\u001b[49m(X_train, y_train, seq_len\u001b[38;5;241m=\u001b[39mseq_length, target\u001b[38;5;241m=\u001b[39m\u001b[38;5;124m'\u001b[39m\u001b[38;5;124mtarget\u001b[39m\u001b[38;5;124m'\u001b[39m)\n\u001b[0;32m      9\u001b[0m valid_ds \u001b[38;5;241m=\u001b[39m TimeSeriesDataSet(X_val, y_val, seq_len\u001b[38;5;241m=\u001b[39mseq_length, target\u001b[38;5;241m=\u001b[39m\u001b[38;5;124m'\u001b[39m\u001b[38;5;124mtarget\u001b[39m\u001b[38;5;124m'\u001b[39m)\n",
      "\u001b[1;31mNameError\u001b[0m: name 'TimeSeriesDataSet' is not defined"
     ]
    }
   ],
   "source": [
    "# Set the sequence length (look-back window)\n",
    "seq_length = 60\n",
    "\n",
    "# Split the training data into training and validation data\n",
    "X_train, y_train, X_val, y_val = train_val_split(treated_train_df)\n",
    "\n",
    "# Convert the training and validation data into a TimeSeriesDataSet\n",
    "train_ds = TimeSeriesDataSet(X_train, y_train, seq_len=seq_length, target='target')\n",
    "valid_ds = TimeSeriesDataSet(X_val, y_val, seq_len=seq_length, target='target')\n"
   ]
  },
  {
   "cell_type": "markdown",
   "metadata": {},
   "source": [
    "# Basic Time Series Transformers"
   ]
  }
 ],
 "metadata": {
  "kernelspec": {
   "display_name": "Python 3",
   "language": "python",
   "name": "python3"
  },
  "language_info": {
   "codemirror_mode": {
    "name": "ipython",
    "version": 3
   },
   "file_extension": ".py",
   "mimetype": "text/x-python",
   "name": "python",
   "nbconvert_exporter": "python",
   "pygments_lexer": "ipython3",
   "version": "3.11.9"
  }
 },
 "nbformat": 4,
 "nbformat_minor": 2
}
